Workbook

Sheet Leia-me
B2: Orçamento do projeto Pick-to-Light (flow rack)
B3: Arquitetura A: coletor MovFast + concentrador + displays. RFID com pulseira fica como melhoria futura. Revisão 26/10/2026.
B5: COMO USAR
B6: • Células em AZUL são entradas editáveis (quantidades, preços, premissas). Células em PRETO são fórmulas: não editar.
B7: • Células com fundo AMARELO são premissas/estimativas que precisam de cotação ou confirmação.
B8: • Aba 'Estações': números de endereços por estação, extraídos de wms_endereco (esteiras 1 e 2) em 23/10/2026. Corrija qualquer número direto ali: todo o orçamento recalcula.
B9: • Coluna 'Piloto' (S/N) na aba 'Estações' define quais estações entram no cenário piloto (POC: 04 e 27).
B10: • Aba 'Preços': catálogo de peças com fonte e data. Itens marcados 'Estimativa' devem ser cotados antes da compra.
B11: • A operação completa inclui as estações do piloto (não somar os dois).
B13: ABAS
B14: Resumo: comparativo de todos os cenários (piloto x operação completa), contingência e investimento total recomendado.
B15: Premissas: câmbio, fator de importação, custos-hora, horas de montagem/instalação, metragens, reserva, frete, contingência.
... B45: • Ajuste de 26/10/2026 (tarde): 2 displays E+Q nos andares 4-5 (antes 4) e 2 zonas por lado no baixo giro (antes 4), o que reduz os módulos E+Q de 485 para 251; sinal luminoso de baixo giro por estação.

Sheet Resumo
A1: Resumo do orçamento, Pick-to-Light
A2: Piloto: estações marcadas 'S' na aba Estações (POC: 04 e 27). A operação completa já inclui o piloto. Hardware, instalação e treinamento; software nas linhas abaixo.
A3: Cenário | B3: Descrição | C3: Piloto (R$) | D3: Operação completa (R$) | E3: Por estação, completo (R$) | F3: Completo + contingência (R$)
A4: A interno, só materiais (12 V) | B4: Peças, infraestrutura e frete; montagem própria | C4: ='A-Interno'!F21 -> 14510.641 | D4: ='A-Interno'!G21 -> 222482.89 | E4: =D4/Estações!$O$43 -> 5562.0722 | F4: =D4*(1+Premissas!$B$28) -> 244731.18
A5: A interno, só materiais (variante 5 V) | B5: Sem reguladores, fonte 5 V, mais cabo de força | C5: ='A-Interno'!F40 -> 14731.687 | D5: ='A-Interno'!G40 -> 227135.49 | E5: =D5/Estações!$O$43 -> 5678.3872 | F5: =D5*(1+Premissas!$B$28) -> 249849.04
A6: A interno, materiais + mão de obra | B6: Montagem, instalação, comissionamento e treinamento internos | C6: ='A-Interno'!F34 -> 19211.497 | D6: ='A-Interno'!G34 -> 304755.49 | E6: =D6/Estações!$O$43 -> 7618.8873 | F6: =D6*(1+Premissas!$B$28) -> 335231.04
A7: A terceiros, T1 (PCB própria via EMS) | B7: Placas próprias fabricadas/montadas por terceiros + instalação | C7: ='A-Terceiros'!F13 -> 34967.366 | D7: ='A-Terceiros'!G13 -> 335486.89 | E7: =D7/Estações!$O$43 -> 8387.1722 | F7: =D7*(1+Premissas!$B$28) -> 369035.58
A8: A terceiros, T2 (PTL comercial importado) | B8: Hardware PTL pronto + instalação | C8: ='A-Terceiros'!F25 -> 41680.748 | D8: ='A-Terceiros'!G25 -> 763124.99 | E8: =D8/Estações!$O$43 -> 19078.125 | F8: =D8*(1+Premissas!$B$28) -> 839437.49
A9: Melhoria futura: RFID com pulseira | B9: Acréscimo sobre a A: tags nas caixas + pulseiras (não incluído no investimento) | C9: ='RFID-futuro'!F8 -> 1759.9511 | D9: ='RFID-futuro'!G8 -> 33039.793 | E9: =D9/Estações!$O$43 -> 825.99481 | F9: =D9*(1+Premissas!$B$28) -> 36343.772
A11: Desenvolvimento de software (interno)
A12: Arquitetura A (app próprio) | B12: ="Horas: "&TEXT(Software!C15,"#,##0") -> Horas: 1,144 | D12: =Software!D15 -> 118727.55
A13: Melhoria futura: RFID (acréscimo) | B13: ="Horas: "&TEXT(Software!C16,"#,##0") -> Horas: 80 | D13: =Software!D16 -> 8302.6258
A15: Investimento total, Arquitetura A (proposta) | B15: A interno com contingência + software da Arquitetura A | F15: =F6+D12 -> 453958.59
A17: POC (bancada + estações 04 e 27) | B17: Hardware com contingência (aba POC); software da POC é interno | C17: =POC!E29 -> 22469.468
A19: Volume da operação (informado): ~3.000 volumes/dia e 250.000 a 270.000 produtos separados por dia.

Sheet Premissas
A1: Premissa | B1: Valor | C1: Unidade | D1: Fonte / observação
A2: Câmbio USD/BRL (comercial) | B2: 5.0371 | C2: R$/US$ | D2: renovainvest.com.br/dolar-hoje, fechamento de 23/10/2026 (13h07, mercado fechado)
A3: Fator de importação (frete + impostos + despacho) sobre o valor FOB | B3: 1.9 | C3: x | D3: Estimativa para importação formal de eletrônicos (II + IPI + PIS/COFINS + ICMS + frete). Confirmar com Comércio Exterior.
A4: Salário médio técnico eletrônico (CLT) | B4: 2846.84 | C4: R$/mês | D4: salario.com.br, CBO 313215, atualizado em 08/10/2026 (CAGED)
A5: Salário médio analista de desenvolvimento de sistemas (CLT) | B5: 8458.3 | C5: R$/mês | D5: salario.com.br, CBO 212405, atualizado em 08/10/2026 (CAGED)
A6: Salário médio auxiliar de logística (operador da estação) | B6: 2009.59 | C6: R$/mês | D6: salario.com.br, CBO 414140, atualizado em 08/10/2026 (CAGED)
A7: Fator de encargos e benefícios sobre salário | B7: 2 | C7: x | D7: Estimativa usual (encargos + benefícios + provisões). Ajustar com RH.
A8: Horas produtivas por mês | B8: 163 | C8: h | D8: 44 h/semana com ausências
A9: Custo-hora técnico (calculado) | B9: =$B$4*$B$7/$B$8 -> 34.930552 | C9: R$/h | D9: Fórmula: salário × encargos ÷ horas
A10: Custo-hora desenvolvimento interno (calculado) | B10: =$B$5*$B$7/$B$8 -> 103.78282 | C10: R$/h | D10: Fórmula: salário × encargos ÷ horas (antes: R$ 60/h fixo)
A11: Custo-hora operador (calculado) | B11: =$B$6*$B$7/$B$8 -> 24.657546 | C11: R$/h | D11: Usado no tempo de treinamento dos operadores
A12: Montagem, Módulo Q | B12: 0.25 | C12: h/un | D12: Estimativa: display + botão + carcaça + teste
A13: Montagem, Nó de coluna | B13: 0.75 | C13: h/un | D13: Estimativa: placa base, soldas, gravação de firmware, teste
A14: Montagem, Módulo E+Q | B14: 1 | C14: h/un | D14: Estimativa
A15: Montagem, Concentrador (gabinete completo) | B15: 2 | C15: h/un | D15: Estimativa
A16: Instalação, parte fixa por estação | B16: 4 | C16: h/estação | D16: Concentrador, energia, cabo de rede, passagem da frente para o corredor
A17: Instalação por Módulo Q (fixar, ligar, etiquetar) | B17: 0.15 | C17: h/un | D17: Estimativa
A18: Instalação por Nó de coluna | B18: 0.25 | C18: h/un | D18: Estimativa
A19: Instalação por Módulo E+Q | B19: 0.35 | C19: h/un | D19: Estimativa
A20: Instalação de canaleta | B20: 0.08 | C20: h/m | D20: Estimativa (cerca de 5 min por metro)
A21: Testes e comissionamento por estação | B21: 4 | C21: h/estação | D21: Teste de cada endereço + caixa de teste ponta a ponta
A22: Fator de hora extra na instalação e comissionamento | B22: 1.5 | C22: x | D22: Instalação fora do horário de separação (hora extra 50%). Use 1,0 se for feita no horário normal.
A23: Turnos de separação por dia | B23: 2 | C23: turnos | D23: CONFIRMAR com a operação (define pessoas a treinar)
... A44: Montagem final + gravação + teste por módulo vindo da EMS (T1) | B44: 0.1 | C44: h/un | D44: Estimativa

Sheet Estações
A1: Rua (estação) | B1: Segmento | C1: Tipo | D1: Piloto (S/N) | E1: Total de endereços | F1: Alto giro 0-3 (Módulos Q) | G1: Alto giro 4-5 (endereços) | H1: E+Q alto giro 4-5 (2 zonas) | I1: Baixo giro (endereços) | J1: Zonas baixo giro (E+Q) | K1: Nós de coluna | L1: Prédios do baixo giro | M1: Módulos E+Q | N1: Segmentos de barramento | O1: Concentrador
A2: 03 | B2: Medicamento | C2: Ponta | D2: N | E2: 131 | F2: 29 | G2: 20 | H2: 2 | I2: 82 | J2: 2 | K2: 10 | L2: 13 | M2: =H2+J2 -> 4 | N2: =K2+M2 -> 14 | O2: 1
A3: 04 | B3: Medicamento | C3: Comum | D3: S | E3: 201 | F3: 29 | G3: 16 | H3: 2 | I3: 156 | J3: 4 | K3: 10 | L3: 24 | M3: =H3+J3 -> 6 | N3: =K3+M3 -> 16 | O3: 1
A4: 05 | B4: Medicamento | C4: Comum | D4: N | E4: 209 | F4: 29 | G4: 20 | H4: 2 | I4: 160 | J4: 4 | K4: 10 | L4: 25 | M4: =H4+J4 -> 6 | N4: =K4+M4 -> 16 | O4: 1
A5: 06 | B5: Medicamento | C5: Comum | D5: N | E5: 209 | F5: 29 | G5: 20 | H5: 2 | I5: 160 | J5: 4 | K5: 10 | L5: 25 | M5: =H5+J5 -> 6 | N5: =K5+M5 -> 16 | O5: 1
A6: 07 | B6: Medicamento | C6: Comum | D6: N | E6: 209 | F6: 29 | G6: 20 | H6: 2 | I6: 160 | J6: 4 | K6: 10 | L6: 25 | M6: =H6+J6 -> 6 | N6: =K6+M6 -> 16 | O6: 1
A7: 08 | B7: Medicamento | C7: Comum | D7: N | E7: 205 | F7: 29 | G7: 16 | H7: 2 | I7: 160 | J7: 4 | K7: 10 | L7: 25 | M7: =H7+J7 -> 6 | N7: =K7+M7 -> 16 | O7: 1
A8: 09 | B8: Medicamento | C8: Esquina | D8: N | E8: 241 | F8: 29 | G8: 20 | H8: 2 | I8: 192 | J8: 5 | K8: 10 | L8: 29 | M8: =H8+J8 -> 7 | N8: =K8+M8 -> 17 | O8: 1
A9: 10 | B9: Medicamento | C9: Esquina | D9: N | E9: 237 | F9: 29 | G9: 20 | H9: 2 | I9: 188 | J9: 5 | K9: 10 | L9: 29 | M9: =H9+J9 -> 7 | N9: =K9+M9 -> 17 | O9: 1
A10: 11 | B10: Medicamento | C10: Comum | D10: N | E10: 205 | F10: 29 | G10: 16 | H10: 2 | I10: 160 | J10: 4 | K10: 10 | L10: 25 | M10: =H10+J10 -> 6 | N10: =K10+M10 -> 16 | O10: 1
A11: 12 | B11: Medicamento | C11: Comum | D11: N | E11: 209 | F11: 29 | G11: 20 | H11: 2 | I11: 160 | J11: 4 | K11: 10 | L11: 25 | M11: =H11+J11 -> 6 | N11: =K11+M11 -> 16 | O11: 1
A12: 13 | B12: Medicamento | C12: Comum | D12: N | E12: 203 | F12: 29 | G12: 14 | H12: 2 | I12: 160 | J12: 4 | K12: 10 | L12: 25 | M12: =H12+J12 -> 6 | N12: =K12+M12 -> 16 | O12: 1
A13: 14 | B13: Medicamento | C13: Comum | D13: N | E13: 209 | F13: 29 | G13: 20 | H13: 2 | I13: 160 | J13: 4 | K13: 10 | L13: 25 | M13: =H13+J13 -> 6 | N13: =K13+M13 -> 16 | O13: 1
... A41: 45 | B41: Perfumaria | C41: Ponta | D41: N | E41: 181 | F41: 35 | G41: 15 | H41: 2 | I41: 131 | J41: 4 | K41: 10 | L41: 25 | M41: =H41+J41 -> 6 | N41: =K41+M41 -> 16 | O41: 1
A43: Total da operação completa | D43: =COUNTA(A2:A41) -> 40 | E43: =SUM(E2:E41) -> 7981 | F43: =SUM(F2:F41) -> 1280 | G43: =SUM(G2:G41) -> 612 | H43: =SUM(H2:H41) -> 80 | I43: =SUM(I2:I41) -> 6089 | J43: =SUM(J2:J41) -> 171 | K43: =SUM(K2:K41) -> 400 | L43: =SUM(L2:L41) -> 1026 | ... O43: =SUM(O2:O41) -> 40
A44: Total do piloto (Piloto = S) | D44: =COUNTIF(D2:D41,"S") -> 2 | E44: =SUMIF($D$2:$D$41,"S",E2:E41) -> 382 | F44: =SUMIF($D$2:$D$41,"S",F2:F41) -> 64 | G44: =SUMIF($D$2:$D$41,"S",G2:G41) -> 31 | H44: =SUMIF($D$2:$D$41,"S",H2:H41) -> 4 | I44: =SUMIF($D$2:$D$41,"S",I2:I41) -> 287 | J44: =SUMIF($D$2:$D$41,"S",J2:J41) -> 8 | K44: =SUMIF($D$2:$D$41,"S",K2:K41) -> 20 | L44: =SUMIF($D$2:$D$41,"S",L2:L41) -> 49 | ... O44: =SUMIF($D$2:$D$41,"S",O2:O41) -> 2
A46: Coluna D (Piloto) = quantidade de estações nas linhas de total. Fonte: wms_endereco (cd_esteira 1 e 2), exportado em 23/10/2026; rua 90 (Marketing/Almoxarifado) desconsiderada.
A47: Regras: Alto giro = prédios 001-010; andares 4-5 com 2 displays E+Q por estação (zonas 001-005 e 006-010). Baixo giro = demais prédios (corredor, 015 e esquinas): 2 zonas E+Q por lado do corredor; esquinas com zonas de 4 prédios.
A48: Segmentos de barramento = 1 cabo de entrada por nó e por módulo E+Q (ligação em cadeia nas 2 portas do concentrador).

Sheet Preços
A1: Código | B1: Item | C1: Unidade | D1: Preço (R$) | E1: Preço (US$) | F1: Fonte / data | G1: Status
A2: P01 | B2: Display 7 segmentos 4 dígitos TM1637 (usa 3 dígitos, quantidade) | C2: un | D2: 9.98 | F2: Usinainfo, Módulo Display TM1637 4 dígitos vermelho, 23/10/2026 (Pix) | G2: Cotado
A3: P02 | B3: Display 7 segmentos 8 dígitos MAX7219 (endereço) | C3: un | D3: 20.17 | F3: Usinainfo, Display MAX7219 8 dígitos SPI, 23/10/2026 (Pix) | G3: Cotado
A4: P03 | B4: Microcontrolador Raspberry Pi Pico (RP2040) | C4: un | D4: 39.9 | F4: MakerHero, Raspberry Pi Pico, 23/10/2026 | G4: Cotado
A5: P04 | B5: Módulo transceptor RS-485 (MAX485) | C5: un | D5: 8.9 | F5: Saravati, Módulo conversor TTL/RS485 MAX485, 23/10/2026 | G5: Cotado
A6: P05 | B6: Placa do concentrador RP2040 + Ethernet W5500 (W5500-EVB-Pico) | C6: un | D6: =E6*Premissas!$B$2*Premissas!$B$3 -> 119.63112 | E6: 12.5 | F6: SparkFun DEV-19958 US$ 12,50, 23/10/2026; convertido com câmbio × fator de importação | G6: Cotado (US$)
A7: P06 | B7: Fonte Mean Well LRS-150-12 (12 V / 12,5 A / 150 W) | C7: un | D7: 189.98 | F7: MCEIG (fontesmeanwell.com.br), 23/10/2026. Carga estimada < 40 W por estação: folga para expansão | G7: Cotado
A8: P07 | B8: Fonte Mean Well LRS-150-5 (5 V / 22 A), variante 5 V | C8: un | D8: 185 | F8: Estimativa (mesma família da LRS-150-12), cotar | G8: Estimativa
A9: P08 | B9: Regulador step-down 12 V → 5 V (mini, 3 A) | C9: un | D9: 8 | F9: Estimativa de mercado, cotar | G9: Estimativa
A10: P09 | B10: Botão de confirmação metálico 16 mm com anel de LED 12 V (momentâneo) | C10: un | D10: 18 | F10: Estimativa de mercado, cotar. Botão plástico comum não aguenta ~6.000 toques/dia por estação | G10: Estimativa
A11: P10 | B11: Conector RJ45 fêmea para placa (jack) | C11: un | D11: 2.5 | F11: Estimativa, cotar | G11: Estimativa
A12: P11 | B12: Plug RJ45 Cat5e (macho) | C12: un | D12: 0.8 | F12: Estimativa (pote com 100), cotar | G12: Estimativa
A13: P12 | B13: Cabo Cat5e (por metro) | C13: m | D13: =1229.41/305 -> 4.0308525 | F13: KaBuM, Cabo Cat5e Fortrek FK500C 305 m R$ 1.229,41 (Pix), 23/10/2026 | G13: Cotado
A14: P13 | B14: Carcaça do Módulo Q (impressão 3D PETG ou caixa plástica pequena) | C14: un | D14: 5 | F14: Estimativa | G14: Estimativa
A15: P14 | B15: Carcaça do Módulo E+Q / Nó de coluna | C15: un | D15: 15 | F15: Estimativa | G15: Estimativa
A16: P15 | B16: Placa base universal + bornes (nó / módulo E+Q) | C16: un | D16: 10 | F16: Estimativa | G16: Estimativa
A17: P16 | B17: Gabinete do concentrador ventilado (caixa IP54 + cooler 40 mm 12 V + filtro) | C17: un | D17: 90 | F17: Estimativa, cotar (ambiente com poeira e calor) | G17: Estimativa
A18: P17 | B18: Trilho DIN + bornes + disjuntor 2 A | C18: kit | D18: 45 | F18: Estimativa, cotar | G18: Estimativa
A19: P18 | B19: Canaleta / perfil de fixação dos módulos (por metro) | C19: m | D19: 9 | F19: Estimativa (canaleta PVC 20×10 mm em barra de 2 m), cotar | G19: Estimativa
A20: P19 | B20: Fixações diversas por estação (abraçadeiras, parafusos, etiquetas, plugs da rede) | C20: kit | D20: 40 | F20: Estimativa | G20: Estimativa
A21: P20 | B21: Switch 24 portas Gigabit TP-Link TL-SG1024DE | C21: un | D21: 769.32 | F21: KaBuM, 23/10/2026 (Pix) | G21: Cotado
A22: P21 | B22: (não usado) LED guia de coluna, retirado em 26/10/2026 | C22: LED | D22: 0 | F22: Não faz parte do projeto | G22: Retirado
A23: P22 | B23: Tag NFC NTAG213 adesiva 13,56 MHz | C23: un | D23: 2.37 | F23: Loja RFID, lote 100 un R$ 237,41 à vista, 23/10/2026 (lote de 5.000 deve sair mais barato) | G23: Cotado
A24: P23 | B24: Suporte/proteção da tag na caixa retornável | C24: un | D24: 0.5 | F24: Estimativa | G24: Estimativa
A25: P24 | B25: ESP32-C3 Super Mini (pulseira) | C25: un | D25: 29.89 | F25: Usinainfo, 23/10/2026 (Pix) | G25: Cotado
... A28: P27 | B28: Carcaça 3D + pulseira velcro | C28: un | D28: 20 | F28: Estimativa | G28: Estimativa
A29: P29 | B29: Módulo PTL comercial 3 dígitos + botão (RS-485) | C29: un | D29: =E29*Premissas!$B$2*Premissas!$B$3 -> 287.1147 | E29: 30 | F29: Alibaba, Sophia T-P3: US$ 32 (1-299 un) / US$ 28 (300+), 23/10/2026; média US$ 30 | G29: Cotado (US$)
A30: P30 | B30: Módulo PTL comercial endereço + quantidade (display alfanumérico) | C30: un | D30: =E30*Premissas!$B$2*Premissas!$B$3 -> 622.08185 | E30: 65 | F30: Estimativa (não há preço público), solicitar cotação a fornecedores | G30: Estimativa
A31: P31 | B31: Controlador/gateway PTL comercial por estação | C31: un | D31: =E31*Premissas!$B$2*Premissas!$B$3 -> 2105.5078 | E31: 220 | F31: Estimativa (não há preço público), solicitar cotação | G31: Estimativa
A32: P32 | B32: PCB própria montada por EMS, Módulo Q (MCU + display 0,56" + botão + 2× RJ45) | C32: un | D32: =E32*Premissas!$B$2*Premissas!$B$3 -> 86.13441 | E32: 9 | F32: Estimativa com base na tabela de montagem JLCPCB (jlcpcb.com/help/article/pcb-assembly-price) + componentes | G32: Estimativa
A33: P33 | B33: PCB própria montada por EMS, Módulo E+Q | C33: un | D33: =E33*Premissas!$B$2*Premissas!$B$3 -> 210.55078 | E33: 22 | F33: Estimativa (idem) | G33: Estimativa
A34: P34 | B34: PCB própria montada por EMS, Concentrador (MCU + Ethernet + 2× RS-485) | C34: un | D34: =E34*Premissas!$B$2*Premissas!$B$3 -> 334.96715 | E34: 35 | F34: Estimativa (idem) | G34: Estimativa
A35: P35 | B35: Engenharia de projeto das PCBs (terceirizada, valor único) | C35: projeto | D35: 15000 | F35: Estimativa, solicitar orçamento a design house | G35: Estimativa
A36: P36 | B36: Leitor RFID UHF de pulso comercial (FEIG HyWEAR Compact), referência | C36: un | D36: =E36*Premissas!$B$2*Premissas!$B$3 -> 9541.7785 | E36: 997 | F36: atlasRFIDstore, US$ 997, 22/10/2026 (UHF; não lê tags NFC) | G36: Cotado (US$)
A37: P38 | B37: Cabo PP 3×1,0 mm² (por metro) | C37: m | D37: =913.31/100 -> 9.1331 | F37: KaBuM, Cabo PP 3×1,00 mm² flexível preto 100 m R$ 913,31 (Pix), 26/10/2026 | G37: Cotado
A38: P39 | B38: Plugue 2P+T 10 A + prensa-cabo | C38: un | D38: 12 | F38: Estimativa, cotar | G38: Estimativa
A39: P40 | B39: DPS / protetor de surto 275 V para o concentrador | C39: un | D39: 35 | F39: Estimativa, cotar | G39: Estimativa
A40: P41 | B40: Kit rede: alicate de crimpar + testador de cabo + 40 m Cat5e Nexans + 10 RJ45 | C40: kit | D40: 285.99 | F40: KaBuM, produto 386101, 26/10/2026 (Pix) | G40: Cotado
A41: P42 | B41: Bancada de eletrônica: estação de solda + multímetro + consumíveis | C41: kit | D41: 700 | F41: Estimativa, cotar | G41: Estimativa
A42: P43 | B42: Nobreak 720 VA bivolt (Intelbras XNB) para o switch | C42: un | D42: 368.1 | F42: KaBuM via escorregaopreco.com.br, oferta atualizada ~28 dias antes de 26/10/2026 | G42: Cotado
...

Sheet Composição
A1: Conjunto | B1: Código | C1: Item | D1: Qtd por unidade | E1: Preço unit. (R$) | F1: Subtotal (R$)
A2: Módulo Q | B2: P01 | C2: =INDEX(Preços!$B:$B,MATCH(B2,Preços!$A:$A,0)) -> Display 7 segmentos 4 dígitos TM1637 (usa 3 dígitos, quantidade) | D2: 1 | E2: =INDEX(Preços!$D:$D,MATCH(B2,Preços!$A:$A,0)) -> 9.98 | F2: =D2*E2 -> 9.98
A3: Módulo Q | B3: P09 | C3: =INDEX(Preços!$B:$B,MATCH(B3,Preços!$A:$A,0)) -> Botão de confirmação metálico 16 mm com anel de LED 12 V (momentâneo) | D3: 1 | E3: =INDEX(Preços!$D:$D,MATCH(B3,Preços!$A:$A,0)) -> 18 | F3: =D3*E3 -> 18
A4: Módulo Q | B4: P13 | C4: =INDEX(Preços!$B:$B,MATCH(B4,Preços!$A:$A,0)) -> Carcaça do Módulo Q (impressão 3D PETG ou caixa plástica pequena) | D4: 1 | E4: =INDEX(Preços!$D:$D,MATCH(B4,Preços!$A:$A,0)) -> 5 | F4: =D4*E4 -> 5
A5: Módulo Q | B5: P10 | C5: =INDEX(Preços!$B:$B,MATCH(B5,Preços!$A:$A,0)) -> Conector RJ45 fêmea para placa (jack) | D5: 1 | E5: =INDEX(Preços!$D:$D,MATCH(B5,Preços!$A:$A,0)) -> 2.5 | F5: =D5*E5 -> 2.5
A6: Módulo Q | B6: P12 | C6: =INDEX(Preços!$B:$B,MATCH(B6,Preços!$A:$A,0)) -> Cabo Cat5e (por metro) | D6: 2 | E6: =INDEX(Preços!$D:$D,MATCH(B6,Preços!$A:$A,0)) -> 4.0308525 | F6: =D6*E6 -> 8.0617049
A7: Módulo Q | B7: P11 | C7: =INDEX(Preços!$B:$B,MATCH(B7,Preços!$A:$A,0)) -> Plug RJ45 Cat5e (macho) | D7: 2 | E7: =INDEX(Preços!$D:$D,MATCH(B7,Preços!$A:$A,0)) -> 0.8 | F7: =D7*E7 -> 1.6
A8: Custo unitário, Módulo Q | F8: =SUM(F2:F7) -> 45.141705
A10: Nó de coluna | B10: P03 | C10: =INDEX(Preços!$B:$B,MATCH(B10,Preços!$A:$A,0)) -> Microcontrolador Raspberry Pi Pico (RP2040) | D10: 1 | E10: =INDEX(Preços!$D:$D,MATCH(B10,Preços!$A:$A,0)) -> 39.9 | F10: =D10*E10 -> 39.9
A11: Nó de coluna | B11: P04 | C11: =INDEX(Preços!$B:$B,MATCH(B11,Preços!$A:$A,0)) -> Módulo transceptor RS-485 (MAX485) | D11: 1 | E11: =INDEX(Preços!$D:$D,MATCH(B11,Preços!$A:$A,0)) -> 8.9 | F11: =D11*E11 -> 8.9
A12: Nó de coluna | B12: P08 | C12: =INDEX(Preços!$B:$B,MATCH(B12,Preços!$A:$A,0)) -> Regulador step-down 12 V → 5 V (mini, 3 A) | D12: 1 | E12: =INDEX(Preços!$D:$D,MATCH(B12,Preços!$A:$A,0)) -> 8 | F12: =D12*E12 -> 8
A13: Nó de coluna | B13: P15 | C13: =INDEX(Preços!$B:$B,MATCH(B13,Preços!$A:$A,0)) -> Placa base universal + bornes (nó / módulo E+Q) | D13: 1 | E13: =INDEX(Preços!$D:$D,MATCH(B13,Preços!$A:$A,0)) -> 10 | F13: =D13*E13 -> 10
A14: Nó de coluna | B14: P10 | C14: =INDEX(Preços!$B:$B,MATCH(B14,Preços!$A:$A,0)) -> Conector RJ45 fêmea para placa (jack) | D14: 6 | E14: =INDEX(Preços!$D:$D,MATCH(B14,Preços!$A:$A,0)) -> 2.5 | F14: =D14*E14 -> 15
A15: Nó de coluna | B15: P14 | C15: =INDEX(Preços!$B:$B,MATCH(B15,Preços!$A:$A,0)) -> Carcaça do Módulo E+Q / Nó de coluna | D15: 1 | E15: =INDEX(Preços!$D:$D,MATCH(B15,Preços!$A:$A,0)) -> 15 | F15: =D15*E15 -> 15
A16: Custo unitário, Nó de coluna | F16: =SUM(F10:F15) -> 96.8
A18: Módulo E+Q | B18: P02 | C18: =INDEX(Preços!$B:$B,MATCH(B18,Preços!$A:$A,0)) -> Display 7 segmentos 8 dígitos MAX7219 (endereço) | D18: 1 | E18: =INDEX(Preços!$D:$D,MATCH(B18,Preços!$A:$A,0)) -> 20.17 | F18: =D18*E18 -> 20.17
A19: Módulo E+Q | B19: P01 | C19: =INDEX(Preços!$B:$B,MATCH(B19,Preços!$A:$A,0)) -> Display 7 segmentos 4 dígitos TM1637 (usa 3 dígitos, quantidade) | D19: 1 | E19: =INDEX(Preços!$D:$D,MATCH(B19,Preços!$A:$A,0)) -> 9.98 | F19: =D19*E19 -> 9.98
A20: Módulo E+Q | B20: P03 | C20: =INDEX(Preços!$B:$B,MATCH(B20,Preços!$A:$A,0)) -> Microcontrolador Raspberry Pi Pico (RP2040) | D20: 1 | E20: =INDEX(Preços!$D:$D,MATCH(B20,Preços!$A:$A,0)) -> 39.9 | F20: =D20*E20 -> 39.9
A21: Módulo E+Q | B21: P04 | C21: =INDEX(Preços!$B:$B,MATCH(B21,Preços!$A:$A,0)) -> Módulo transceptor RS-485 (MAX485) | D21: 1 | E21: =INDEX(Preços!$D:$D,MATCH(B21,Preços!$A:$A,0)) -> 8.9 | F21: =D21*E21 -> 8.9
A22: Módulo E+Q | B22: P08 | C22: =INDEX(Preços!$B:$B,MATCH(B22,Preços!$A:$A,0)) -> Regulador step-down 12 V → 5 V (mini, 3 A) | D22: 1 | E22: =INDEX(Preços!$D:$D,MATCH(B22,Preços!$A:$A,0)) -> 8 | F22: =D22*E22 -> 8
A23: Módulo E+Q | B23: P09 | C23: =INDEX(Preços!$B:$B,MATCH(B23,Preços!$A:$A,0)) -> Botão de confirmação metálico 16 mm com anel de LED 12 V (momentâneo) | D23: 1 | E23: =INDEX(Preços!$D:$D,MATCH(B23,Preços!$A:$A,0)) -> 18 | F23: =D23*E23 -> 18
A24: Módulo E+Q | B24: P10 | C24: =INDEX(Preços!$B:$B,MATCH(B24,Preços!$A:$A,0)) -> Conector RJ45 fêmea para placa (jack) | D24: 2 | E24: =INDEX(Preços!$D:$D,MATCH(B24,Preços!$A:$A,0)) -> 2.5 | F24: =D24*E24 -> 5
A25: Módulo E+Q | B25: P14 | C25: =INDEX(Preços!$B:$B,MATCH(B25,Preços!$A:$A,0)) -> Carcaça do Módulo E+Q / Nó de coluna | D25: 1 | E25: =INDEX(Preços!$D:$D,MATCH(B25,Preços!$A:$A,0)) -> 15 | F25: =D25*E25 -> 15
A26: Módulo E+Q | B26: P15 | C26: =INDEX(Preços!$B:$B,MATCH(B26,Preços!$A:$A,0)) -> Placa base universal + bornes (nó / módulo E+Q) | D26: 1 | E26: =INDEX(Preços!$D:$D,MATCH(B26,Preços!$A:$A,0)) -> 10 | F26: =D26*E26 -> 10
A27: Custo unitário, Módulo E+Q | F27: =SUM(F18:F26) -> 134.95
A29: Concentrador 12 V | B29: P05 | C29: =INDEX(Preços!$B:$B,MATCH(B29,Preços!$A:$A,0)) -> Placa do concentrador RP2040 + Ethernet W5500 (W5500-EVB-Pico) | D29: 1 | E29: =INDEX(Preços!$D:$D,MATCH(B29,Preços!$A:$A,0)) -> 119.63112 | F29: =D29*E29 -> 119.63112
A30: Concentrador 12 V | B30: P04 | C30: =INDEX(Preços!$B:$B,MATCH(B30,Preços!$A:$A,0)) -> Módulo transceptor RS-485 (MAX485) | D30: 2 | E30: =INDEX(Preços!$D:$D,MATCH(B30,Preços!$A:$A,0)) -> 8.9 | F30: =D30*E30 -> 17.8
A31: Concentrador 12 V | B31: P06 | C31: =INDEX(Preços!$B:$B,MATCH(B31,Preços!$A:$A,0)) -> Fonte Mean Well LRS-150-12 (12 V / 12,5 A / 150 W) | D31: 1 | E31: =INDEX(Preços!$D:$D,MATCH(B31,Preços!$A:$A,0)) -> 189.98 | F31: =D31*E31 -> 189.98
A32: Concentrador 12 V | B32: P08 | C32: =INDEX(Preços!$B:$B,MATCH(B32,Preços!$A:$A,0)) -> Regulador step-down 12 V → 5 V (mini, 3 A) | D32: 1 | E32: =INDEX(Preços!$D:$D,MATCH(B32,Preços!$A:$A,0)) -> 8 | F32: =D32*E32 -> 8
A33: Concentrador 12 V | B33: P16 | C33: =INDEX(Preços!$B:$B,MATCH(B33,Preços!$A:$A,0)) -> Gabinete do concentrador ventilado (caixa IP54 + cooler 40 mm 12 V + filtro) | D33: 1 | E33: =INDEX(Preços!$D:$D,MATCH(B33,Preços!$A:$A,0)) -> 90 | F33: =D33*E33 -> 90
A34: Concentrador 12 V | B34: P17 | C34: =INDEX(Preços!$B:$B,MATCH(B34,Preços!$A:$A,0)) -> Trilho DIN + bornes + disjuntor 2 A | D34: 1 | E34: =INDEX(Preços!$D:$D,MATCH(B34,Preços!$A:$A,0)) -> 45 | F34: =D34*E34 -> 45
A35: Concentrador 12 V | B35: P10 | C35: =INDEX(Preços!$B:$B,MATCH(B35,Preços!$A:$A,0)) -> Conector RJ45 fêmea para placa (jack) | D35: 2 | E35: =INDEX(Preços!$D:$D,MATCH(B35,Preços!$A:$A,0)) -> 2.5 | F35: =D35*E35 -> 5
A36: Concentrador 12 V | B36: P38 | C36: =INDEX(Preços!$B:$B,MATCH(B36,Preços!$A:$A,0)) -> Cabo PP 3×1,0 mm² (por metro) | D36: 3 | E36: =INDEX(Preços!$D:$D,MATCH(B36,Preços!$A:$A,0)) -> 9.1331 | F36: =D36*E36 -> 27.3993
A37: Concentrador 12 V | B37: P39 | C37: =INDEX(Preços!$B:$B,MATCH(B37,Preços!$A:$A,0)) -> Plugue 2P+T 10 A + prensa-cabo | D37: 1 | E37: =INDEX(Preços!$D:$D,MATCH(B37,Preços!$A:$A,0)) -> 12 | F37: =D37*E37 -> 12
A38: Concentrador 12 V | B38: P40 | C38: =INDEX(Preços!$B:$B,MATCH(B38,Preços!$A:$A,0)) -> DPS / protetor de surto 275 V para o concentrador | D38: 1 | E38: =INDEX(Preços!$D:$D,MATCH(B38,Preços!$A:$A,0)) -> 35 | F38: =D38*E38 -> 35
A39: Custo unitário, Concentrador 12 V | F39: =SUM(F29:F38) -> 549.81043
A41: Concentrador 5 V | B41: P05 | C41: =INDEX(Preços!$B:$B,MATCH(B41,Preços!$A:$A,0)) -> Placa do concentrador RP2040 + Ethernet W5500 (W5500-EVB-Pico) | D41: 1 | E41: =INDEX(Preços!$D:$D,MATCH(B41,Preços!$A:$A,0)) -> 119.63112 | F41: =D41*E41 -> 119.63112
A42: Concentrador 5 V | B42: P04 | C42: =INDEX(Preços!$B:$B,MATCH(B42,Preços!$A:$A,0)) -> Módulo transceptor RS-485 (MAX485) | D42: 2 | E42: =INDEX(Preços!$D:$D,MATCH(B42,Preços!$A:$A,0)) -> 8.9 | F42: =D42*E42 -> 17.8
A43: Concentrador 5 V | B43: P07 | C43: =INDEX(Preços!$B:$B,MATCH(B43,Preços!$A:$A,0)) -> Fonte Mean Well LRS-150-5 (5 V / 22 A), variante 5 V | D43: 1 | E43: =INDEX(Preços!$D:$D,MATCH(B43,Preços!$A:$A,0)) -> 185 | F43: =D43*E43 -> 185
A44: Concentrador 5 V | B44: P16 | C44: =INDEX(Preços!$B:$B,MATCH(B44,Preços!$A:$A,0)) -> Gabinete do concentrador ventilado (caixa IP54 + cooler 40 mm 12 V + filtro) | D44: 1 | E44: =INDEX(Preços!$D:$D,MATCH(B44,Preços!$A:$A,0)) -> 90 | F44: =D44*E44 -> 90
...

Sheet A-Interno
A1: Item | B1: Base de cálculo | C1: Qtd piloto | D1: Qtd completo | E1: Preço unit. (R$) | F1: Total piloto (R$) | G1: Total completo (R$)
A2: Arquitetura A, produção e montagem interna (12 V)
A3: Módulos Q (alto giro 0-3) | B3: endereços alto giro 0-3 × (1 + reserva) | C3: =ROUNDUP(Estações!$F$44*(1+Premissas!$B$26),0) -> 71 | D3: =ROUNDUP(Estações!$F$43*(1+Premissas!$B$26),0) -> 1408 | E3: =Composição!$F$8 -> 45.141705 | F3: =C3*E3 -> 3205.061 | G3: =D3*E3 -> 63559.521
A4: Nós de coluna (alto giro) | B4: prédios do alto giro × (1 + reserva) | C4: =ROUNDUP(Estações!$K$44*(1+Premissas!$B$26),0) -> 22 | D4: =ROUNDUP(Estações!$K$43*(1+Premissas!$B$26),0) -> 440 | E4: =Composição!$F$16 -> 96.8 | F4: =C4*E4 -> 2129.6 | G4: =D4*E4 -> 42592
A5: Módulos E+Q (A4/A5 + zonas baixo giro) | B5: displays E+Q × (1 + reserva) | C5: =ROUNDUP(Estações!$M$44*(1+Premissas!$B$26),0) -> 14 | D5: =ROUNDUP(Estações!$M$43*(1+Premissas!$B$26),0) -> 277 | E5: =Composição!$F$27 -> 134.95 | F5: =C5*E5 -> 1889.3 | G5: =D5*E5 -> 37381.15
A6: Concentradores 12 V | B6: 1 por estação × (1 + reserva) | C6: =ROUNDUP(Estações!$O$44*(1+Premissas!$B$26),0) -> 3 | D6: =ROUNDUP(Estações!$O$43*(1+Premissas!$B$26),0) -> 44 | E6: =Composição!$F$39 -> 549.81043 | F6: =C6*E6 -> 1649.4313 | G6: =D6*E6 -> 24191.659
A7: Cabo de barramento Cat5e (m) | B7: segmentos × m por segmento + 2 saídas × m de saída por estação | C7: =Estações!$N$44*Premissas!$B$29+Estações!$O$44*2*Premissas!$B$30 -> 120 | D7: =Estações!$N$43*Premissas!$B$29+Estações!$O$43*2*Premissas!$B$30 -> 2433 | E7: =Preços!$D$13 -> 4.0308525 | F7: =C7*E7 -> 483.7023 | G7: =D7*E7 -> 9807.064
A8: Plugs RJ45 do barramento | B8: 2 por segmento + 4 por estação (saídas) | C8: =Estações!$N$44*2+Estações!$O$44*4 -> 72 | D8: =Estações!$N$43*2+Estações!$O$43*4 -> 1462 | E8: =Preços!$D$12 -> 0.8 | F8: =C8*E8 -> 57.6 | G8: =D8*E8 -> 1169.6
A9: Canaleta / perfil de fixação (m) | B9: prédios alto giro × (largura × linhas + descida) + 2 lados × corredor + travessia, por estação | C9: =Estações!$K$44*(Premissas!$B$31*Premissas!$B$32+Premissas!$B$33)+Estações!$O$44*2*Premissas!$B$34+Estações!$O$44*Premissas!$B$35 -> 54 | D9: =Estações!$K$43*(Premissas!$B$31*Premissas!$B$32+Premissas!$B$33)+Estações!$O$43*2*Premissas!$B$34+Estações!$O$43*Premissas!$B$35 -> 1080 | E9: =Preços!$D$19 -> 9 | F9: =C9*E9 -> 486 | G9: =D9*E9 -> 9720
A10: Fixações diversas | B10: 1 kit por estação | C10: =Estações!$O$44 -> 2 | D10: =Estações!$O$43 -> 40 | E10: =Preços!$D$20 -> 40 | F10: =C10*E10 -> 80 | G10: =D10*E10 -> 1600
A11: Sinal luminoso de baixo giro | B11: 1 por estação, ao lado da posição de pega | C11: =Estações!$O$44 -> 2 | D11: =Estações!$O$43 -> 40 | E11: =Preços!$D$48 -> 45 | F11: =C11*E11 -> 90 | G11: =D11*E11 -> 1800
A12: Cabo de rede até a estação (m) | B12: metros por estação | C12: =Estações!$O$44*Premissas!$B$36 -> 100 | D12: =Estações!$O$43*Premissas!$B$36 -> 2000 | E12: =Preços!$D$13 -> 4.0308525 | F12: =C12*E12 -> 403.08525 | G12: =D12*E12 -> 8061.7049
A13: Switch 24 portas | B13: estações ÷ portas por switch (arredondado para cima) | C13: =ROUNDUP(Estações!$O$44/Premissas!$B$37,0) -> 1 | D13: =ROUNDUP(Estações!$O$43/Premissas!$B$37,0) -> 2 | E13: =Preços!$D$21 -> 769.32 | F13: =C13*E13 -> 769.32 | G13: =D13*E13 -> 1538.64
A14: Nobreak do switch | B14: 1 por switch | C14: =C13 -> 1 | D14: =D13 -> 2 | E14: =Preços!$D$42 -> 368.1 | F14: =C14*E14 -> 368.1 | G14: =D14*E14 -> 736.2
A15: Mini rack de parede do switch | B15: 1 por switch | C15: =C13 -> 1 | D15: =D13 -> 2 | E15: =Preços!$D$43 -> 550 | F15: =C15*E15 -> 550 | G15: =D15*E15 -> 1100
A16: Cabo de uplink até a rede corporativa (m) | B16: switches × m de uplink | C16: =C13*Premissas!$B$38 -> 80 | D16: =D13*Premissas!$B$38 -> 160 | E16: =Preços!$D$13 -> 4.0308525 | F16: =C16*E16 -> 322.4682 | G16: =D16*E16 -> 644.93639
A17: Pontos de tomada 220 V novos | B17: estações × % sem tomada próxima (arredondado para cima) | C17: =ROUNDUP(Estações!$O$44*Premissas!$B$39,0) -> 1 | D17: =ROUNDUP(Estações!$O$43*Premissas!$B$39,0) -> 20 | E17: =Preços!$D$45 -> 350 | F17: =C17*E17 -> 350 | G17: =D17*E17 -> 7000
A18: Ferramentas de rede (crimpar e testar) | B18: 1 kit (compra única) | C18: =1 -> 1 | D18: =1 -> 1 | E18: =Preços!$D$40 -> 285.99 | F18: =C18*E18 -> 285.99 | G18: =D18*E18 -> 285.99
A19: Bancada de eletrônica (solda, multímetro) | B19: 1 kit (compra única) | C19: =1 -> 1 | D19: =1 -> 1 | E19: =Preços!$D$41 -> 700 | F19: =C19*E19 -> 700 | G19: =D19*E19 -> 700
A20: Frete das compras | B20: % sobre peças e infraestrutura acima | E20: =Premissas!$B$27 -> 0.05 | F20: =E20*SUM(F3:F19) -> 690.9829 | G20: =E20*SUM(G3:G19) -> 10594.423
A21: SUBTOTAL MATERIAIS, Arquitetura A (12 V) | F21: =SUM(F3:F20) -> 14510.641 | G21: =SUM(G3:G20) -> 222482.89
A23: Mão de obra interna e treinamento
A24: Montagem Módulos Q (h) | B24: módulos × h/un | C24: =C3*Premissas!$B$12 -> 17.75 | D24: =D3*Premissas!$B$12 -> 352 | E24: =Premissas!$B$9 -> 34.930552 | F24: =C24*E24 -> 620.0173 | G24: =D24*E24 -> 12295.554
A25: Montagem Nós de coluna (h) | B25: nós × h/un | C25: =C4*Premissas!$B$13 -> 16.5 | D25: =D4*Premissas!$B$13 -> 330 | E25: =Premissas!$B$9 -> 34.930552 | F25: =C25*E25 -> 576.35411 | G25: =D25*E25 -> 11527.082
A26: Montagem Módulos E+Q (h) | B26: módulos × h/un | C26: =C5*Premissas!$B$14 -> 14 | D26: =D5*Premissas!$B$14 -> 277 | E26: =Premissas!$B$9 -> 34.930552 | F26: =C26*E26 -> 489.02773 | G26: =D26*E26 -> 9675.7629
A27: Montagem Concentradores (h) | B27: concentradores × h/un | C27: =C6*Premissas!$B$15 -> 6 | D27: =D6*Premissas!$B$15 -> 88 | E27: =Premissas!$B$9 -> 34.930552 | F27: =C27*E27 -> 209.58331 | G27: =D27*E27 -> 3073.8886
A28: Instalação nas estações (h) | B28: (fixo por estação + Q + nós + E+Q + canaleta) × fator hora extra | C28: =(Estações!$O$44*Premissas!$B$16+Estações!$F$44*Premissas!$B$17+Estações!$K$44*Premissas!$B$18+Estações!$M$44*Premissas!$B$19+C9*Premissas!$B$20)*Premissas!$B$22 -> 46.68 | D28: =(Estações!$O$43*Premissas!$B$16+Estações!$F$43*Premissas!$B$17+Estações!$K$43*Premissas!$B$18+Estações!$M$43*Premissas!$B$19+D9*Premissas!$B$20)*Premissas!$B$22 -> 939.375 | E28: =Premissas!$B$9 -> 34.930552 | F28: =C28*E28 -> 1630.5582 | G28: =D28*E28 -> 32812.887
A29: Testes e comissionamento (h) | B29: estações × h/estação × fator hora extra | C29: =Estações!$O$44*Premissas!$B$21*Premissas!$B$22 -> 12 | D29: =Estações!$O$43*Premissas!$B$21*Premissas!$B$22 -> 240 | E29: =Premissas!$B$9 -> 34.930552 | F29: =C29*E29 -> 419.16663 | G29: =D29*E29 -> 8383.3325
A30: Treinamento dos operadores (h) | B30: estações × turnos × h por operador | C30: =Estações!$O$44*Premissas!$B$23*Premissas!$B$24 -> 8 | D30: =Estações!$O$43*Premissas!$B$23*Premissas!$B$24 -> 160 | E30: =Premissas!$B$11 -> 24.657546 | F30: =C30*E30 -> 197.26037 | G30: =D30*E30 -> 3945.2074
A31: Treinamento da manutenção (h) | B31: total da equipe | C31: =Premissas!$B$25 -> 16 | D31: =Premissas!$B$25 -> 16 | E31: =Premissas!$B$9 -> 34.930552 | F31: =C31*E31 -> 558.88883 | G31: =D31*E31 -> 558.88883
A32: SUBTOTAL MÃO DE OBRA E TREINAMENTO | C32: =SUM(C24:C31) -> 136.93 | D32: =SUM(D24:D31) -> 2402.375 | F32: =SUM(F24:F31) -> 4700.8565 | G32: =SUM(G24:G31) -> 82272.604
A34: TOTAL, Arquitetura A interna (materiais + mão de obra) | F34: =F21+F32 -> 19211.497 | G34: =G21+G32 -> 304755.49
A36: Variante 5 V (materiais)
A37: (−) Reguladores step-down dispensados | B37: nós + módulos E+Q + concentradores | C37: =-(C4+C5+C6) -> -39 | D37: =-(D4+D5+D6) -> -761 | E37: =Preços!$D$9 -> 8 | F37: =C37*E37 -> -312 | G37: =D37*E37 -> -6088
A38: (±) Fonte 5 V no lugar da 12 V | B38: concentradores | C38: =C6 -> 3 | D38: =D6 -> 44 | E38: =(Preços!$D$8-Preços!$D$7) -> -4.98 | F38: =C38*E38 -> -14.94 | G38: =D38*E38 -> -219.12
A39: (+) Cabo de força extra para injeção de 5 V (m) | B39: metros por estação | C39: =Estações!$O$44*Premissas!$B$42 -> 60 | D39: =Estações!$O$43*Premissas!$B$42 -> 1200 | E39: =Preços!$D$37 -> 9.1331 | F39: =C39*E39 -> 547.986 | G39: =D39*E39 -> 10959.72
A40: SUBTOTAL MATERIAIS, variante 5 V | F40: =F21+SUM(F37:F39) -> 14731.687 | G40: =G21+SUM(G37:G39) -> 227135.49

Sheet A-Terceiros
A1: Item | B1: Base de cálculo | C1: Qtd piloto | D1: Qtd completo | E1: Preço unit. (R$) | F1: Total piloto (R$) | G1: Total completo (R$)
A2: T1, Placas próprias fabricadas e montadas por EMS (cada módulo com seu microcontrolador)
A3: Módulo Q, PCB montada + carcaça | B3: endereços alto giro 0-3 × (1 + reserva) | C3: =ROUNDUP(Estações!$F$44*(1+Premissas!$B$26),0) -> 71 | D3: =ROUNDUP(Estações!$F$43*(1+Premissas!$B$26),0) -> 1408 | E3: =Preços!$D$32+Preços!$D$14 -> 91.13441 | F3: =C3*E3 -> 6470.5431 | G3: =D3*E3 -> 128317.25
A4: Módulo E+Q, PCB montada + carcaça + botão | B4: displays E+Q × (1 + reserva) | C4: =ROUNDUP(Estações!$M$44*(1+Premissas!$B$26),0) -> 14 | D4: =ROUNDUP(Estações!$M$43*(1+Premissas!$B$26),0) -> 277 | E4: =Preços!$D$33+Preços!$D$15+Preços!$D$10 -> 243.55078 | F4: =C4*E4 -> 3409.7109 | G4: =D4*E4 -> 67463.566
A5: Concentrador, PCB montada + fonte + gabinete + alimentação | B5: estações × (1 + reserva) | C5: =ROUNDUP(Estações!$O$44*(1+Premissas!$B$26),0) -> 3 | D5: =ROUNDUP(Estações!$O$43*(1+Premissas!$B$26),0) -> 44 | E5: =Preços!$D$34+Preços!$D$7+Preços!$D$17+Preços!$D$18+Preços!$D$37*3+Preços!$D$38*1+Preços!$D$39*1 -> 734.34645 | F5: =C5*E5 -> 2203.0394 | G5: =D5*E5 -> 32311.244
A6: Cabo do barramento em cadeia (m) | B6: Q × m em cadeia + E+Q × m por segmento + saídas | C6: =Estações!$F$44*Premissas!$B$43+Estações!$M$44*Premissas!$B$29+Estações!$O$44*2*Premissas!$B$30 -> 124 | D6: =Estações!$F$43*Premissas!$B$43+Estações!$M$43*Premissas!$B$29+Estações!$O$43*2*Premissas!$B$30 -> 2513 | E6: =Preços!$D$13 -> 4.0308525 | F6: =C6*E6 -> 499.8257 | G6: =D6*E6 -> 10129.532
A7: Plugs RJ45 do barramento | B7: 2 por módulo + 4 por estação | C7: =(Estações!$F$44+Estações!$M$44)*2+Estações!$O$44*4 -> 160 | D7: =(Estações!$F$43+Estações!$M$43)*2+Estações!$O$43*4 -> 3222 | E7: =Preços!$D$12 -> 0.8 | F7: =C7*E7 -> 128 | G7: =D7*E7 -> 2577.6
A8: Infraestrutura (canaleta, rede, switches, energia, ferramentas) | B8: igual à Arquitetura A | F8: =SUM('A-Interno'!F9:F19) -> 4404.9634 | G8: =SUM('A-Interno'!G9:G19) -> 33187.471
A9: Engenharia de projeto das PCBs (valor único) | B9: 1 projeto | C9: =1 -> 1 | D9: =1 -> 1 | E9: =Preços!$D$35 -> 15000 | F9: =C9*E9 -> 15000 | G9: =D9*E9 -> 15000
A10: Montagem final + gravação + teste (h) | B10: módulos e concentradores recebidos × h/un | C10: =(C3+C4+C5)*Premissas!$B$44 -> 8.8 | D10: =(D3+D4+D5)*Premissas!$B$44 -> 172.9 | E10: =Premissas!$B$9 -> 34.930552 | F10: =C10*E10 -> 307.38886 | G10: =D10*E10 -> 6039.4925
A11: Instalação + comissionamento (h) | B11: como na Arquitetura A, sem nós de coluna | C11: =(Estações!$O$44*Premissas!$B$16+Estações!$F$44*Premissas!$B$17+Estações!$M$44*Premissas!$B$19+'A-Interno'!C9*Premissas!$B$20+Estações!$O$44*Premissas!$B$21)*Premissas!$B$22 -> 51.18 | D11: =(Estações!$O$43*Premissas!$B$16+Estações!$F$43*Premissas!$B$17+Estações!$M$43*Premissas!$B$19+'A-Interno'!D9*Premissas!$B$20+Estações!$O$43*Premissas!$B$21)*Premissas!$B$22 -> 1029.375 | E11: =Premissas!$B$9 -> 34.930552 | F11: =C11*E11 -> 1787.7457 | G11: =D11*E11 -> 35956.637
A12: Treinamento (operadores e manutenção) | B12: igual à Arquitetura A | F12: =SUM('A-Interno'!F30:F31) -> 756.1492 | G12: =SUM('A-Interno'!G30:G31) -> 4504.0962
A13: TOTAL T1, PCB própria (EMS) | F13: =SUM(F3:F12) -> 34967.366 | G13: =SUM(G3:G12) -> 335486.89
A15: T2, Sistema PTL comercial importado (hardware pronto; software de integração continua interno)
A16: Módulos PTL 3 dígitos (alto giro 0-3) | B16: endereços × (1 + reserva) | C16: =ROUNDUP(Estações!$F$44*(1+Premissas!$B$26),0) -> 71 | D16: =ROUNDUP(Estações!$F$43*(1+Premissas!$B$26),0) -> 1408 | E16: =Preços!$D$29 -> 287.1147 | F16: =C16*E16 -> 20385.144 | G16: =D16*E16 -> 404257.5
A17: Módulos PTL endereço + quantidade | B17: displays E+Q × (1 + reserva) | C17: =ROUNDUP(Estações!$M$44*(1+Premissas!$B$26),0) -> 14 | D17: =ROUNDUP(Estações!$M$43*(1+Premissas!$B$26),0) -> 277 | E17: =Preços!$D$30 -> 622.08185 | F17: =C17*E17 -> 8709.1459 | G17: =D17*E17 -> 172316.67
A18: Controlador/gateway PTL por estação | B18: estações | C18: =Estações!$O$44 -> 2 | D18: =Estações!$O$43 -> 40 | E18: =Preços!$D$31 -> 2105.5078 | F18: =C18*E18 -> 4211.0156 | G18: =D18*E18 -> 84220.312
A19: Fonte 12 V + gabinete + alimentação por estação | B19: estações | C19: =Estações!$O$44 -> 2 | D19: =Estações!$O$43 -> 40 | E19: =Preços!$D$7+Preços!$D$17+Preços!$D$18+Preços!$D$37*3+Preços!$D$38*1+Preços!$D$39*1 -> 399.3793 | F19: =C19*E19 -> 798.7586 | G19: =D19*E19 -> 15975.172
A20: Cabo do barramento em cadeia (m) | B20: Q × m em cadeia + E+Q × m por segmento + saídas | C20: =Estações!$F$44*Premissas!$B$43+Estações!$M$44*Premissas!$B$29+Estações!$O$44*2*Premissas!$B$30 -> 124 | D20: =Estações!$F$43*Premissas!$B$43+Estações!$M$43*Premissas!$B$29+Estações!$O$43*2*Premissas!$B$30 -> 2513 | E20: =Preços!$D$13 -> 4.0308525 | F20: =C20*E20 -> 499.8257 | G20: =D20*E20 -> 10129.532
A21: Plugs RJ45 do barramento | B21: 2 por módulo + 4 por estação | C21: =(Estações!$F$44+Estações!$M$44)*2+Estações!$O$44*4 -> 160 | D21: =(Estações!$F$43+Estações!$M$43)*2+Estações!$O$43*4 -> 3222 | E21: =Preços!$D$12 -> 0.8 | F21: =C21*E21 -> 128 | G21: =D21*E21 -> 2577.6
A22: Infraestrutura (canaleta, rede, switches, energia, ferramentas) | B22: igual à Arquitetura A | F22: =SUM('A-Interno'!F9:F19) -> 4404.9634 | G22: =SUM('A-Interno'!G9:G19) -> 33187.471
A23: Instalação + comissionamento (h) | B23: como na Arquitetura A, sem nós de coluna | C23: =(Estações!$O$44*Premissas!$B$16+Estações!$F$44*Premissas!$B$17+Estações!$M$44*Premissas!$B$19+'A-Interno'!C9*Premissas!$B$20+Estações!$O$44*Premissas!$B$21)*Premissas!$B$22 -> 51.18 | D23: =(Estações!$O$43*Premissas!$B$16+Estações!$F$43*Premissas!$B$17+Estações!$M$43*Premissas!$B$19+'A-Interno'!D9*Premissas!$B$20+Estações!$O$43*Premissas!$B$21)*Premissas!$B$22 -> 1029.375 | E23: =Premissas!$B$9 -> 34.930552 | F23: =C23*E23 -> 1787.7457 | G23: =D23*E23 -> 35956.637
A24: Treinamento (operadores e manutenção) | B24: igual à Arquitetura A | F24: =SUM('A-Interno'!F30:F31) -> 756.1492 | G24: =SUM('A-Interno'!G30:G31) -> 4504.0962
A25: TOTAL T2, PTL comercial importado | F25: =SUM(F16:F24) -> 41680.748 | G25: =SUM(G16:G24) -> 763124.99
A27: Valores em US$ convertidos por câmbio × fator de importação (aba Premissas). Itens de PTL comercial sem preço público devem ser cotados com fornecedores (ex.: ATOP, Aioi, fornecedores nacionais). Frete nacional não aplicado aqui: os itens principais são importados (frete no fator de importação).

Sheet RFID-futuro
A1: Item | B1: Base de cálculo | C1: Qtd piloto | D1: Qtd completo | E1: Preço unit. (R$) | F1: Total piloto (R$) | G1: Total completo (R$)
A2: Melhoria futura (não entra na POC nem na implantação inicial): tag NFC na caixa + pulseira no operador
A3: Tags NFC nas caixas retornáveis (frota) | B3: frota de caixas (piloto: proporcional às estações) | C3: =ROUNDUP(Premissas!$B$40*Estações!$O$44/Estações!$O$43,0) -> 250 | D3: =Premissas!$B$40 -> 5000 | E3: =Composição!$F$60 -> 2.87 | F3: =C3*E3 -> 717.5 | G3: =D3*E3 -> 14350
A4: Associação tag ↔ caixa (cadastro inicial) (h) | B4: 30 s por caixa | C4: =C3*30/3600 -> 2.0833333 | D4: =D3*30/3600 -> 41.666667 | E4: =Premissas!$B$9 -> 34.930552 | F4: =C4*E4 -> 72.771984 | G4: =D4*E4 -> 1455.4397
A5: Pulseiras NFC (ESP32-C3 + PN532 + bateria) | B5: estações × pulseiras por estação | C5: =ROUNDUP(Estações!$O$44*Premissas!$B$41,0) -> 5 | D5: =ROUNDUP(Estações!$O$43*Premissas!$B$41,0) -> 88 | E5: =Composição!$F$56 -> 127.54 | F5: =C5*E5 -> 637.7 | G5: =D5*E5 -> 11223.52
A6: Carregador USB das pulseiras | B6: 1 por estação | C6: =Estações!$O$44 -> 2 | D6: =Estações!$O$43 -> 40 | E6: =Preços!$D$44 -> 35 | F6: =C6*E6 -> 70 | G6: =D6*E6 -> 1400
A7: Montagem das pulseiras (h) | B7: 1,5 h por pulseira | C7: =C5*1.5 -> 7.5 | D7: =D5*1.5 -> 132 | E7: =Premissas!$B$9 -> 34.930552 | F7: =C7*E7 -> 261.97914 | G7: =D7*E7 -> 4610.8329
A8: ACRÉSCIMO DO RFID sobre a Arquitetura A | F8: =SUM(F3:F7) -> 1759.9511 | G8: =SUM(G3:G7) -> 33039.793
A10: Referência: Arquitetura A + RFID | B10: aba A-Interno + acréscimo acima | F10: ='A-Interno'!F34+F8 -> 20971.449 | G10: ='A-Interno'!G34+G8 -> 337795.28
A12: Referência de mercado, leitor de pulso comercial | B12: FEIG HyWEAR (UHF) por pulseira, não lê NFC; exigiria tags UHF | C12: =C5 -> 5 | D12: =D5 -> 88 | E12: =Preços!$D$36 -> 9541.7785 | F12: =C12*E12 -> 47708.893 | G12: =D12*E12 -> 839676.51
A14: O hardware e o software da Arquitetura A já ficam preparados para receber a leitura RFID depois. O leitor fixo na estação (antiga opção B2) foi retirado do projeto em 26/10/2026.

Sheet Software
A1: Componente | B1: Arquitetura | C1: Horas estimadas | D1: Custo (R$) | E1: Observação
A2: Serviço PTL (API REST + MQTT + regras de separação) | B2: A e B | C2: 240 | D2: =C2*Premissas!$B$10 -> 24907.877 | E2: Núcleo: abre/fecha caixa, divide por estação/zona, ordena pela rota
A3: Integração Sybase ASE (tabelas PTL, views, procedures) | B3: A e B | C3: 120 | D3: =C3*Premissas!$B$10 -> 12453.939 | E3: Leitura de itens da caixa e gravação de eventos/log
A4: Integração API do sistema BHT (informações da caixa) | B4: A e B | C4: 60 | D4: =C4*Premissas!$B$10 -> 6226.9693 | E4: Consulta da caixa e, se possível, liberação para a próxima estação
A5: App coletor Android (A1, app próprio) | B5: A | C5: 160 | D5: =C5*Premissas!$B$10 -> 16605.252 | E5: Leitura com gatilho para abrir/fechar, progresso da caixa
A6: Tela no WMS PowerBuilder para o coletor (A2) | B6: A2 | C6: 80 | D6: =C6*Premissas!$B$10 -> 8302.6258 | E6: Alternativa ao app; grava a leitura em tabela consumida pelo serviço
A7: Firmware do concentrador (Ethernet + MQTT + 2 barramentos RS-485) | B7: A e B | C7: 120 | D7: =C7*Premissas!$B$10 -> 12453.939 | E7: Base no protótipo MicroPython já validado
A8: Firmware dos nós de coluna e módulos E+Q | B8: A e B | C8: 100 | D8: =C8*Premissas!$B$10 -> 10378.282 | E8: Protocolo de barramento, endereçamento, auto-teste
A9: Leitura RFID pela pulseira (melhoria futura) | B9: RFID | C9: 80 | D9: =C9*Premissas!$B$10 -> 8302.6258 | E9: Fora do escopo inicial
A10: Painel de monitoramento (gestão e TI) | B10: A e B | C10: 120 | D10: =C10*Premissas!$B$10 -> 12453.939 | E10: Status das estações, módulos com falha, produtividade
A11: Interface de controle: qual LED falhou + cadastro de LED por endereço (tela + botão) | B11: A e B | C11: 40 | D11: =C11*Premissas!$B$10 -> 4151.3129 | E11: Diagnóstico no firmware (sem resposta, display sem ACK, botão travado), modo cadastro e tabela ptl_mapa_led
A12: Implantação do servidor (VM, broker MQTT, backup, monitoração) | B12: A e B | C12: 24 | D12: =C12*Premissas!$B$10 -> 2490.7877 | E12: Considera VM em infraestrutura já existente; sem compra de servidor
A13: Testes integrados, piloto e homologação | B13: A e B | C13: 120 | D13: =C13*Premissas!$B$10 -> 12453.939 | E13: Inclui ajustes na POC (estações 04 e 27)
A14: Documentação e treinamento | B14: A e B | C14: 40 | D14: =C14*Premissas!$B$10 -> 4151.3129 | E14: Operação, manutenção e suporte
A15: TOTAL, Arquitetura A com app próprio (A1) | C15: =SUMIF(B2:B14,"A e B",C2:C14)+SUMIF(B2:B14,"A",C2:C14) -> 1144 | D15: =C15*Premissas!$B$10 -> 118727.55 | E15: Com a tela no WMS (A2) no lugar do app: troque o item A1 (160 h) pelo A2 (80 h).
A16: Melhoria futura: acréscimo do RFID | C16: =SUMIF(B2:B14,"RFID",C2:C14) -> 80 | D16: =C16*Premissas!$B$10 -> 8302.6258
A18: Custo-hora de desenvolvimento calculado na aba Premissas (salário de mercado × encargos ÷ horas). É custo interno da equipe, não desembolso extra, a menos que o desenvolvimento seja contratado.

Sheet POC
A1: POC: bancada + estações 04 e 27 (Arquitetura A, coletor)
A2: Fase 1 valida o hardware e o software na bancada; fase 2 instala nas estações 04 (Medicamento) e 27 (Perfumaria). As estações da POC são as marcadas 'S' na aba Estações.
A3: Item | B3: Base de cálculo | C3: Qtd | D3: Preço unit. (R$) | E3: Total (R$)
A4: Fase 1, bancada (1 coluna de alto giro, 1 zona de cada tipo)
A5: Concentrador 12 V completo | B5: gabinete, fonte, placa, alimentação | C5: 1 | D5: =Composição!$F$39 -> 549.81043 | E5: =C5*D5 -> 549.81043
A6: Nó de coluna | B6: 1 prédio de alto giro | C6: 1 | D6: =Composição!$F$16 -> 96.8 | E6: =C6*D6 -> 96.8
A7: Módulos Q | B7: 4 andares (0 a 3) do prédio | C7: 4 | D7: =Composição!$F$8 -> 45.141705 | E7: =C7*D7 -> 180.56682
A8: Módulos E+Q | B8: 1 zona dos andares 4-5 + 1 zona do baixo giro | C8: 2 | D8: =Composição!$F$27 -> 134.95 | E8: =C8*D8 -> 269.9
A9: Sinal luminoso de baixo giro | B9: barra âmbar | C9: 1 | D9: =Preços!$D$48 -> 45 | E9: =C9*D9 -> 45
A10: Cabo Cat5e (m) | B10: barramento e ligações da bancada | C10: 20 | D10: =Preços!$D$13 -> 4.0308525 | E10: =C10*D10 -> 80.617049
A11: Plugs RJ45 | C11: 20 | D11: =Preços!$D$12 -> 0.8 | E11: =C11*D11 -> 16
A12: Painel de MDF com longarina | B12: simula a prateleira | C12: 1 | D12: =Preços!$D$46 -> 150 | E12: =C12*D12 -> 150
A13: Switch 5 portas | B13: rede da bancada | C13: 1 | D13: =Preços!$D$47 -> 90 | E13: =C13*D13 -> 90
A14: Ferramentas de rede (crimpar e testar) | B14: compra única, servem para a fase 2 | C14: 1 | D14: =Preços!$D$40 -> 285.99 | E14: =C14*D14 -> 285.99
A15: Bancada de eletrônica (solda, multímetro) | B15: compra única, serve para a fase 2 | C15: 1 | D15: =Preços!$D$41 -> 700 | E15: =C15*D15 -> 700
A16: Frete das compras | B16: % sobre os itens acima | D16: =Premissas!$B$27 -> 0.05 | E16: =D16*SUM(E5:E15) -> 123.23421
A17: Montagem dos módulos (h) | B17: conc. + nó + 4 Q + 2 E+Q | C17: =Premissas!$B$15+Premissas!$B$13+4*Premissas!$B$12+2*Premissas!$B$14 -> 5.75 | D17: =Premissas!$B$9 -> 34.930552 | E17: =C17*D17 -> 200.85067
A18: Testes de bancada (h) | B18: acender, confirmar, falha, troca e cadastro de LED, 48 h de operação contínua | C18: 16 | D18: =Premissas!$B$9 -> 34.930552 | E18: =C18*D18 -> 558.88883
A19: TOTAL FASE 1, bancada | E19: =SUM(E5:E18) -> 3347.658
A21: Fase 2, instalação nas estações 04 e 27
A22: Materiais, montagem, instalação e treinamento das 2 estações | B22: aba A-Interno, coluna piloto (estações com 'S') | E22: ='A-Interno'!F34 -> 19211.497
A23: (−) Ferramentas já compradas na fase 1 | B23: kit de rede + bancada de eletrônica | E23: =-('A-Interno'!F18+'A-Interno'!F19)*(1+Premissas!$B$27) -> -1035.2895
A24: (−) Módulos da bancada reaproveitados na estação | B24: o concentrador, o nó, os 4 Q e os 2 E+Q da bancada vão para a estação 04 | E24: =-(Composição!$F$39+Composição!$F$16+4*Composição!$F$8+2*Composição!$F$27) -> -1097.0772
A25: TOTAL FASE 2, estações 04 e 27 | E25: =SUM(E22:E24) -> 17079.131
A27: HARDWARE DA POC (fase 1 + fase 2) | E27: =E19+E25 -> 20426.789
A28: Contingência | B28: % sobre o hardware da POC | D28: =Premissas!$B$28 -> 0.1 | E28: =D28*E27 -> 2042.6789
A29: HARDWARE DA POC COM CONTINGÊNCIA (desembolso) | E29: =E27+E28 -> 22469.468
A31: Software para a POC (equipe interna, versão mínima)
A32: Firmware do concentrador, dos nós e dos E+Q | B32: barramento, endereçamento, diagnóstico, cadastro | C32: 160 | D32: =Premissas!$B$10 -> 103.78282 | E32: =C32*D32 -> 16605.252
A33: Serviço PTL, versão mínima | B33: abrir e fechar caixa, acender, confirmar, sinal de baixo giro | C33: 160 | D33: =Premissas!$B$10 -> 103.78282 | E33: =C33*D33 -> 16605.252
A34: Integração Sybase (leitura dos itens da caixa) | B34: views de leitura e gravação de eventos | C34: 60 | D34: =Premissas!$B$10 -> 103.78282 | E34: =C34*D34 -> 6226.9693
A35: App do coletor (A1), versão mínima | B35: leitura com gatilho e progresso da caixa | C35: 100 | D35: =Premissas!$B$10 -> 103.78282 | E35: =C35*D35 -> 10378.282
A36: Interface de controle, versão mínima | B36: falhas de LED e cadastro por endereço | C36: 40 | D36: =Premissas!$B$10 -> 103.78282 | E36: =C36*D36 -> 4151.3129
A37: Testes da bancada e operação assistida | B37: ajustes durante a POC | C37: 80 | D37: =Premissas!$B$10 -> 103.78282 | E37: =C37*D37 -> 8302.6258
A38: SOFTWARE DA POC (horas e custo interno) | C38: =SUM(C32:C37) -> 600 | E38: =SUM(E32:E37) -> 62269.693
A40: Prazo estimado: bancada 3 a 4 semanas; instalação nas 2 estações 1 semana; operação assistida 4 semanas.
A41: O software da POC é a primeira parte do software do projeto (aba Software), não um custo a mais.
